{"cells":[{"cell_type":"markdown","execution_count":null,"metadata":{"tags":[]},"outputs":[],"source":["TSG124 - ‘No credentials were supplied’ error from azdata login\n","===============================================================\n","\n","Description\n","-----------\n","\n","When running `azdata login` is fails with:\n","\n","    ERROR: No credentials were supplied, or the credentials were unavailable or inaccessible.\n","\n","### Steps\n","\n","-   When using `azdata login` from Windows, ensure the machine is domain\n","    joined, and the user that is logged in is part of the same domain as\n","    the domain the Big Data Cluster is joined to, or the domain the user\n","    is part of has a trust relationship with the domain the Big Data\n","    Cluster is part of.\n","-   When using `azdata login` from Linux, ensure the the user has logged\n","    into the domain, using a Kerberos client such as `kinit`."]}],"nbformat":4,"nbformat_minor":5,"metadata":{"kernelspec":{"name":"python3","display_name":"Python 3"},"pansop":{"related":"","test":{"strategy":"","types":null,"disable":{"reason":"","workitems":null,"types":null}},"target":{"current":"","final":""},"internal":{"parameters":null,"symlink":false},"timeout":"0"},"language_info":{"codemirror_mode":"{ Name: \"\", Version: \"\"}","file_extension":"","mimetype":"","name":"","nbconvert_exporter":"","pygments_lexer":"","version":""},"widgets":[]}}